Workbook

Sheet 契約稟議2026
A1: 契 約 稟 議 書
A3: 取引状況 | D3: 有 | N3: 稟議№ | T3: -
A4: 稟議種別 | D4: 既存 | N4: 決裁日
A5: 決済希望スピード | D5: 飛行機 | N5: 申請日 | Q5: 2026 | S5: 年 | T5: 7 | U5: 月 | V5: 28 | W5: 日
A6: 契約の種別 | D6: 人材派遣 | N6: 企業名 | Q6: bring plus | T6: 営業所 | V6: 茨城
A7: 変形労働時間 有/無 | D7: 無 | N7: 申請者 | Q7: 川住 悠希
A8: ■企業情報
A9: 企 業 名 | D9: 第一熱処理工業株式会社 | N9: 工場名 | P9: 成田工場
A10: 住 所 | D10: 〒 | E10: 287-0225 | H10: 千葉県成田市吉岡681-2
A11: 電話番号 | D11: 0476-73-7997 | M11: FAX
A12: 取引企業代表者名 | D12: 曾根光彰 | H12: 窓口担当者⇒ | J12: 部署名 | N12: 役職 | P12: 担当部長 | R12: 名前 | T12: 黒﨑善行
A13: 企業規模 | D13: 資本金 | F13: 3000 | H13: 千万円 | J13: 区分 | L13: 未上場
D14: 創業・設立 | G14: 21903 | L14: 業種 | N14: 生産用機械器具製造業 | S14: 生産品目 | U14: 自動車、建機部品
A15: ■契約内容
A16: 契約部署 | D16: 成田工場 | H16: 作業内容 | J16: 金属製品の検査 | R16: 必要資格 | T16: なし
A17: 契約（予定）日 | D17: 46237 | G17: 契約期間（自） | J17: 46237 | M17: 契約期間（至） | P17: 46285 | S17: 契約更新ヶ月 | U17: 2ヵ月
A18: 欠員・契約人数・工数 | D18: 男性 | E18: 1 | G18: 女性 | H18: 0 | J18: 合計 | K18: =SUM(E18+H18) -> 1 | L18: 入金サイト | N18: 締日 | O18: 20日 | Q18: 入金日 | R18: 翌月20日 | T18: 請求必着日 | V18: 5営業日
A19: 勤務内容 | D19: 勤務時間 | J19: 休憩時間 | M19: 所定労働時間 | P19: 割増請求稼働時間 | S19: 平均稼動日数 | V19: 勤務形態
D20: ① | E20: 0.35416667 | G20: ～ | H20: 0.72916667 | J20: 60 | L20: M | M20: 8 | O20: H | P20: 8 | R20: H超 | S20: 20 | U20: 日 | V20: 日勤
D21: ② | G21: ～ | L21: M | O21: H | R21: H超 | U21: 日 | V21: 日勤
D22: ③ | G22: ～ | L22: M | O22: H | R22: H超 | U22: 日 | V22: 日勤
D23: ④ | G23: ～ | L23: M | O23: H | R23: H超 | U23: 日
A24: 休日 | D24: 土日祝（会社カレンダー有） | J24: 給与支給 | L24: 締日 | N24: 20日 | R24: 支払日 | T24: 翌月15日
A25: ■契約金額／支払単価 /職業分類
A26: 主な作業内容 | D26: 請単価 | F26: 支払単価 | H26: 原価率 | J26: 手当①：名称 | L26: 手当①：支給額 | N26: 手当①：請求額 | P26: 手当②：名称 | R26: 手当②：支給額 | T26: 手当②：請求額 | V26: 交通費（上限）
A27: ① | B27: 一般事務 | D27: 2400 | F27: 1350 | H27: =F27/D27 -> 0.5625 | V27: 13000円
A28: ② | H28: =F28/D28 -> #DIV/0! | V28: 13000円
A29: ③ | H29: =F29/D29 -> #DIV/0!
A30: ④ | H30: =F30/D30 -> #DIV/0!
A31: 割増 | D31: 時間外 | F31: 1.25 | H31: 深夜 | J31: 1.25 | L31: 法定外休出 | N31: 1.25 | P31: 法定外休出 | R31: 1.25 | T31: 時間外６０H超 | V31: 1.5
A32: 職業安定 業務統計 | C32: NO | D32: 小分類 | F32: 職業名 | J32: 地域名 | M32: 基準値（0年） | P32: 地域指数 | R32: 標準基準値×地域指数 | U32: 支払時給との差異
C33: ① | D33: 3401 | F33: =VLOOKUP(D33,職業統計!A3:K440,2,FALSE) -> 一般事務員 | J33: 千葉 | M33: =VLOOKUP(D33,職業統計!A3:K440,3,FALSE) -> 1122 | P33: =VLOOKUP(J33,'別添３（都道府県別）'!C7:D487,2,FALSE)/100 -> 1.067 | R33: =M33*P33 -> 1197.174 | U33: =F27-R33 -> 152.826
C34: ② | F34: =VLOOKUP(D34,職業統計!A4:K441,2,FALSE) -> #N/A | M34: =VLOOKUP(D34,職業統計!A4:K441,3,FALSE) -> #N/A | P34: =VLOOKUP(J34,'別添３（都道府県別）'!C8:D488,2,FALSE)/100 -> #N/A | R34: =M34*P34 -> #N/A | U34: =F28-R34 -> #N/A
C35: ③ | F35: =VLOOKUP(D35,職業統計!A5:K442,2,FALSE) -> #N/A | M35: =VLOOKUP(D35,職業統計!A5:K442,3,FALSE) -> #N/A | P35: =VLOOKUP(J35,'別添３（都道府県別）'!C9:D489,2,FALSE)/100 -> #N/A | R35: =M35*P35 -> #N/A | U35: =F29-R35 -> #N/A
C36: ④ | F36: =VLOOKUP(D36,職業統計!A6:K443,2,FALSE) -> #N/A | M36: =VLOOKUP(D36,職業統計!A6:K443,3,FALSE) -> #N/A | P36: =VLOOKUP(J36,'別添３（都道府県別）'!C10:D490,2,FALSE)/100 -> #N/A | R36: =M36*P36 -> #N/A | U36: =F30-R36 -> #N/A
A38: ■現況及び起案者所見
A39: 事務女性1名の受注。求人依頼・掘起し対応いたします。
A40: ■備考
A41: 現状検査員男性1名の欠員有
A43: ■所長コメント
...

Sheet 職業統計
A1: 職業安 | K1: 別添２
A3: 201 | B3: 会社管理職員 | C3: 1684 | D3: 1916 | E3: 2051 | F3: 2102 | G3: 2250 | H3: 2403 | I3: 2987 | J3: - | K3: 1949
A4: 299 | B4: その他の法人・団体管理職員 | C4: 1554 | D4: 1768 | E4: 1893 | F4: 1939 | G4: 2076 | H4: 2218 | I4: 2757 | J4: 1563 | K4: 1748
A5: 301 | B5: 管理的公務員 | C5: 1334 | D5: 1518 | E5: 1625 | F5: 1665 | G5: 1782 | H5: 1904 | I5: 2367 | J5: - | K5: 1529
A6: 399 | B6: 他に分類されない管理的職業 | C6: 1447 | D6: 1647 | E6: 1762 | F6: 1806 | G6: 1933 | H6: 2065 | I6: 2567 | J6: - | K6: 1665
A7: 401 | B7: 自然科学系研究者 | C7: 1357 | D7: 1544 | E7: 1653 | F7: 1694 | G7: 1813 | H7: 1936 | I7: 2407 | J7: - | K7: 1627
A8: 402 | B8: 人文・社会科学系等研究者 | C8: - | D8: - | E8: - | F8: - | G8: - | H8: - | I8: - | J8: - | K8: -
A9: 501 | B9: 農林水産技術者 | C9: 1152 | D9: 1311 | E9: 1403 | F9: 1438 | G9: 1539 | H9: 1644 | I9: 2044 | J9: - | K9: 1348
A10: 601 | B10: 食品開発技術者 | C10: 1256 | D10: 1429 | E10: 1530 | F10: 1567 | G10: 1678 | H10: 1792 | I10: 2228 | J10: - | K10: 1471
A11: 602 | B11: 電気・電子・電気通信開発技術者 （通信ネットワークを除く） | C11: 1400 | D11: 1593 | E11: 1705 | F11: 1747 | G11: 1870 | H11: 1998 | I11: 2484 | J11: - | K11: 1820
A12: 603 | B12: 機械開発技術者 | C12: 1350 | D12: 1536 | E12: 1644 | F12: 1685 | G12: 1804 | H12: 1926 | I12: 2395 | J12: - | K12: 1745
A13: 604 | B13: 自動車開発技術者 | C13: 1364 | D13: 1552 | E13: 1661 | F13: 1702 | G13: 1822 | H13: 1946 | I13: 2420 | J13: - | K13: 1784
A14: 605 | B14: 輸送用機器開発技術者（自動車を除く） | C14: 1184 | D14: 1347 | E14: 1442 | F14: 1478 | G14: 1582 | H14: 1690 | I14: 2100 | J14: 1192 | K14: 1501
A15: 606 | B15: 金属製錬・材料開発技術者 | C15: 1301 | D15: 1481 | E15: 1585 | F15: 1624 | G15: 1738 | H15: 1857 | I15: 2308 | J15: - | K15: 1589
A16: 607 | B16: 化学製品開発技術者 | C16: 1355 | D16: 1542 | E16: 1650 | F16: 1691 | G16: 1810 | H16: 1934 | I16: 2404 | J16: - | K16: 1637
A17: 699 | B17: その他の開発技術者 | C17: 1339 | D17: 1524 | E17: 1631 | F17: 1671 | G17: 1789 | H17: 1911 | I17: 2375 | J17: - | K17: 1636
A18: 701 | B18: 食品製造技術者 | C18: 1229 | D18: 1399 | E18: 1497 | F18: 1534 | G18: 1642 | H18: 1754 | I18: 2180 | J18: - | K18: 1409
A19: 702 | B19: 電気・電子・電気通信製造技術者 （通信ネットワーク・電気工事技術者を除く） | C19: 1336 | D19: 1520 | E19: 1627 | F19: 1667 | G19: 1785 | H19: 1906 | I19: 2370 | J19: - | K19: 1653
A20: 703 | B20: 電気工事技術者 | C20: 1426 | D20: 1623 | E20: 1737 | F20: 1780 | G20: 1905 | H20: 2035 | I20: 2530 | J20: - | K20: 1865
A21: 704 | B21: 機械製造技術者 | C21: 1279 | D21: 1456 | E21: 1558 | F21: 1596 | G21: 1709 | H21: 1825 | I21: 2269 | J21: - | K21: 1623
A22: 705 | B22: 自動車製造技術者 | C22: 1267 | D22: 1442 | E22: 1543 | F22: 1581 | G22: 1693 | H22: 1808 | I22: 2248 | J22: - | K22: 1577
A23: 706 | B23: 輸送用機器製造技術者（自動車を除く） | C23: 1215 | D23: 1383 | E23: 1480 | F23: 1516 | G23: 1623 | H23: 1734 | I23: 2155 | J23: - | K23: 1492
A24: 707 | B24: 金属製錬・材料製造技術者 | C24: 1238 | D24: 1409 | E24: 1508 | F24: 1545 | G24: 1654 | H24: 1767 | I24: 2196 | J24: - | K24: 1501
A25: 708 | B25: 化学製品製造技術者 | C25: 1264 | D25: 1438 | E25: 1540 | F25: 1577 | G25: 1689 | H25: 1804 | I25: 2242 | J25: - | K25: 1513
A26: 799 | B26: その他の製造技術者 | C26: 1238 | D26: 1409 | E26: 1508 | F26: 1545 | G26: 1654 | H26: 1767 | I26: 2196 | J26: - | K26: 1479
... A36: 903 | B36: プログラマー | C36: 1412 | D36: 1607 | E36: 1720 | F36: 1762 | G36: 1886 | H36: 2015 | I36: 2505 | J36: - | K36: 1926
A37: 999 | B37: その他の情報処理・通信技術者（ソフトウェア開発） | C37: 1471 | D37: 1674 | E37: 1792 | F37: 1836 | G37: 1965 | H37: 2099 | I37: 2610 | J37: 1483 | K37: 1917
A38: 1001 | B38: ＩＴコンサルタント | C38: 1499 | D38: 1706 | E38: 1826 | F38: 1871 | G38: 2003 | H38: 2139 | I38: 2659 | J38: - | K38: 2052
A39: 1002 | B39: ＩＴシステム設計技術者 | C39: 1476 | D39: 1680 | E39: 1798 | F39: 1842 | G39: 1972 | H39: 2106 | I39: 2618 | J39: - | K39: 2018
A40: 1003 | B40: ＩＴプロジェクトマネージャ | C40: 1758 | D40: 2001 | E40: 2141 | F40: 2194 | G40: 2349 | H40: 2509 | I40: 3119 | J40: - | K40: 2272
A41: 1004 | B41: ＩＴシステム運用管理者 | C41: 1384 | D41: 1575 | E41: 1686 | F41: 1727 | G41: 1849 | H41: 1975 | I41: 2455 | J41: - | K41: 1833
A42: 1005 | B42: ＩＴヘルプデスク | C42: 1312 | D42: 1493 | E42: 1598 | F42: 1637 | G42: 1753 | H42: 1872 | I42: 2327 | J42: - | K42: 1674
A43: 1006 | B43: 通信ネットワーク技術者 | C43: 1431 | D43: 1628 | E43: 1743 | F43: 1786 | G43: 1912 | H43: 2042 | I43: 2539 | J43: - | K43: 1933
A44: 1099 | B44: その他の情報処理・通信技術者 （ソフトウェア開発を除く） | C44: 1426 | D44: 1623 | E44: 1737 | F44: 1780 | G44: 1905 | H44: 2035 | I44: 2530 | J44: - | K44: 1907
A45: 1101 | B45: 通信機器操作員 | C45: 1204 | D45: 1370 | E45: 1466 | F45: 1503 | G45: 1609 | H45: 1718 | I45: 2136 | J45: - | K45: 1397
A46: 1199 | B46: 他に分類されない技術の職業 | C46: 1397 | D46: 1590 | E46: 1702 | F46: 1743 | G46: 1866 | H46: 1994 | I46: 2478 | J46: - | K46: 1677
A47: 1201 | B47: 裁判官、検察官、弁護士 | C47: - | D47: - | E47: - | F47: - | G47: - | H47: - | I47: - | J47: - | K47: -
A48: 1202 | B48: 弁理士 | C48: 1372 | D48: 1561 | E48: 1671 | F48: 1712 | G48: 1833 | H48: 1958 | I48: 2434 | J48: 1389 | K48: 2267
A49: 1203 | B49: 司法書士 | C49: 1544 | D49: 1757 | E49: 1881 | F49: 1927 | G49: 2063 | H49: 2203 | I49: 2739 | J49: - | K49: 1877
A50: 1299 | B50: その他の法務の職業 | C50: 1377 | D50: 1567 | E50: 1677 | F50: 1718 | G50: 1840 | H50: 1965 | I50: 2443 | J50: - | K50: 1686
...

Sheet 別添３（都道府県別）
E1: 別添３
B2: 職業安定業務統計による地域指数
D3: 都道府県別地域指数（※）
C5: 全国計 | D5: 100
C7: 北海道 | D7: 94.8
C8: 青森 | D8: 85.4
C9: 岩手 | D9: 87.7
C10: 宮城 | D10: 96.3
C11: 秋田 | D11: 86.9
C12: 山形 | D12: 89.2
C13: 福島 | D13: 92.5
C14: 茨城 | D14: 101
C15: 栃木 | D15: 99.6
C16: 群馬 | D16: 99
C17: 埼玉 | D17: 107.2
... C487: 八重山計 | D487: 88.4

Sheet リスト
B2: 業種
B3: 食料品製造業
B4: 飲料・たばこ・飼料製造業
B5: 繊維工業
B6: 木材・木製品製造業（家具を除く）
B7: 家具・装備品製造業
B8: パルプ・紙・紙加工品製造業
B9: 印刷・同関連業
B10: 化学工業
B11: 石油製品・石炭製品製造業
B12: プラスチック製品製造業（別掲を除く）
B13: ゴム製品製造業
... B27: その他の業種
